<?xml version="1.0" encoding="UTF-8"?>
<robot name ="multipleshapes">

    <material name="blue">
        <color rgba="0 0 1 1"/>
    </material>

    <material name="white">
        <color rgba="1 1 1 1"/>
    </material>

    <link name= "base_link">
        <visual>
            <geometry>
                <box size="0.9 1.6 0.4"/>
            </geometry>
            <origin rpy="0.0 0.0 0.0" xyz="0.0 0.0 0.3"/>
            <material name="blue">
                
            </material>
        </visual>
    </link>

    <link name="front_left">
        <visual>
            <geometry>
                <sphere radius="0.1"/>
            </geometry>
            <origin xyz="-0.24 0.7 -0.5" rpy="0.0 0.0 0.0"/>
        </visual>
    </link>
    
    <joint name="base_to_frontleft" type="fixed">
        <origin xyz="0.0 0.0 0.0" rpy="1.0 0.0 0.0"/>
        <parent link="base_link"/>
        <child link="front_left"/>
    </joint>


    <link name="front_right">
        <visual>
            <geometry>
                <sphere radius="0.1"/>
            </geometry>
            <origin xyz="0.24 0.7 -0.5" rpy="0.0 0.0 0.0"/>
        </visual>
    </link>
    
    <joint name="base_to_frontright" type="fixed">
        <origin xyz="0.0 0.0 0.0" rpy="1.0 0.0 0.0"/>
        <parent link="base_link"/>
        <child link="front_right"/>
    </joint>

    <link name="front_link">
        <visual>
            <geometry>
                <box size="0.1 0.1 1.3"/>
            </geometry>
            <origin xyz="-0.1 0.0 0.0" rpy="0.0 0.0 0.0"/>
        </visual>
    </link>

    <joint name="base_to_front" type="fixed">
        <origin xyz="0.0 0.5 0.0" rpy="0.0 1.57075 0.0"/>
        <parent link="base_link"/>
        <child link="front_link"/>
    </joint>

    <link name="back_link">
        <visual>
            <geometry>
                <box size="0.1 0.1 1.3"/>
            </geometry>
            <origin xyz="-0.1 0.0 0.0" rpy="0.0 0.0 0.0"/>
        </visual>
    </link>

    <joint name="base_to_back" type="fixed">
        <origin xyz="0.0 -0.5 0.0" rpy="0.0 1.57075 0.0"/>
        <parent link="base_link"/>
        <child link="back_link"/>
    </joint>

    <link name = "front_right_wheel">
        <visual>
            <geometry>
                <cylinder radius="0.17" length="0.15"/>
            </geometry>
            <origin rpy="0.0 0.0 0.0" xyz="-0.13 0.0 0.6"/>
            <material name="white"></material>
        </visual>
    </link>

    <joint name="front_to_front_right_wheel" type="continuous">
        <parent link="front_link"/>
        <child link="front_right_wheel"/>    
    </joint>

    <link name = "front_left_wheel">
        <visual>
            <geometry>
                <cylinder radius="0.17" length="0.15"/>
            </geometry>
            <origin rpy="0.0 0.0 0.0" xyz="-0.13 0.0 -0.6"/>
            <material name="white"></material>
        </visual>
    </link>


    <joint name="front_to_front_left_wheel" type="continuous">
        <parent link="front_link"/>
        <child link="front_left_wheel"/>           
    </joint>

    <link name = "back_right_wheel">
        <visual>    
            <geometry>
                <cylinder radius="0.17" length="0.15"/>
            </geometry>
            <origin rpy="0.0 0.0 0.0" xyz="-0.13 0.0 0.6"/>
            <material name="white"></material>
        </visual>
    </link>

    <joint name="back_to_back_right_wheel" type="continuous">
        <parent link="back_link"/>
        <child link="back_right_wheel"/>           
    </joint>

    <link name = "back_left_wheel">
        <visual>
            <geometry>
                <cylinder radius="0.17" length="0.15"/>
            </geometry>
            <origin rpy="0.0 0.0 0.0" xyz="-0.13 0.0 -0.6"/>
            <material name="white"></material>
        </visual>
    </link>

    <joint name="back_to_back_left_wheel" type="continuous">
        <parent link="back_link"/>
        <child link="back_left_wheel"/>           
    </joint>
</robot>