<?xml version="1.0" encoding="UTF-8"?>
<robot name="multipleshapes">

    <material name="blue">
        <color rgba="0 0 1 1" />
    </material>

    <material name="white">
        <color rgba="1 1 1 1" />
    </material>

    <link name="base_link">
        <visual>
            <geometry>
                <cylinder radius="0.5" length="1.3" />
            </geometry>
            <origin rpy="0.0 0.0 0.0" xyz="0.0 0.0 0.9" />
            <material name="blue">
            </material>
        </visual>
        <collision>
            <geometry>
                <cylinder radius="0.5" length="1.3" />
            </geometry>
            <origin rpy="0.0 0.0 0.0" xyz="0.0 0.0 0.9" />
        </collision>
        <inertial>
            <mass value="10.0" />
            <inertia ixx="1.0" ixy="0.0" ixz="0.0" iyy="1.0" iyz="0.0" izz="1.0" />
        </inertial>
    </link>

    <link name="head_link">
        <visual>
            <geometry>
                <sphere radius="0.5" />
            </geometry>
            <material name="white">
            </material>
        </visual>
        <collision>
            <geometry>
                <sphere radius="0.5" />
            </geometry>
        </collision>
        <inertial>
            <mass value="3.0" />
            <inertia ixx="1.0" ixy="0.0" ixz="0.0" iyy="1.0" iyz="0.0" izz="1.0" />
        </inertial>
    </link>

    <joint name="base_to_head_joint" type="fixed">
        <origin xyz="0.0 0.0 1.5" rpy="0.0 0.0 0.0" />
        <parent link="base_link" />
        <child link="head_link" />
    </joint>

    <link name="head_left_link">
        <visual>
            <geometry>
                <sphere radius="0.1" />
            </geometry>
        </visual>
        <collision>
            <geometry>
                <sphere radius="0.1" />
            </geometry>
        </collision>
        <inertial>
            <mass value="1.0" />
            <inertia ixx="1.0" ixy="0.0" ixz="0.0" iyy="1.0" iyz="0.0" izz="1.0" />
        </inertial>
    </link>

    <joint name="base_to_head_left_joint" type="fixed">
        <origin xyz="-0.17 0.5 1.7" rpy="0.0 0.0 0.0" />
        <parent link="base_link" />
        <child link="head_left_link" />
    </joint>


    <link name="head_right_link">
        <visual>
            <geometry>
                <sphere radius="0.1" />
            </geometry>
        </visual>
        <collision>
            <geometry>
                <sphere radius="0.1" />
            </geometry>
        </collision>
        <inertial>
            <mass value="1.0" />
            <inertia ixx="1.0" ixy="0.0" ixz="0.0" iyy="1.0" iyz="0.0" izz="1.0" />
        </inertial>

    </link>

    <joint name="base_to_head_right_joint" type="fixed">
        <origin xyz="0.17 0.5 1.7" rpy="0.0 0.0 0.0" />
        <parent link="base_link" />
        <child link="head_right_link" />
    </joint>

    <link name="leg_link">
        <visual>
            <geometry>
                <box size="0.1 0.1 0.2" />
            </geometry>
        </visual>
        <collision>
            <geometry>
                <box size="0.1 0.1 0.2" />
            </geometry>
        </collision>
        <inertial>
            <mass value="3.0" />
            <inertia ixx="1.0" ixy="0.0" ixz="0.0" iyy="1.0" iyz="0.0" izz="1.0" />
        </inertial>
    </link>

    <joint name="base_to_leg_joint" type="fixed">
        <origin xyz="0.0 -0.3 0.2" rpy="0.0 0.0 0.0" />
        <parent link="base_link" />
        <child link="leg_link" />
    </joint>

    <link name="leg_base_link">
        <visual>
            <geometry>
                <box size="0.5 0.1 0.1" />
            </geometry>
        </visual>
        <collision>
            <geometry>
                <box size="0.5 0.1 0.1" />
            </geometry>
        </collision>
        <inertial>
            <mass value="3.0" />
            <inertia ixx="1.0" ixy="0.0" ixz="0.0" iyy="1.0" iyz="0.0" izz="1.0" />
        </inertial>

    </link>

    <joint name="leg_to_leg_base_joint" type="fixed">
        <origin xyz="0.0 0.0 -0.08" rpy="0.0 0.0 0.0" />
        <parent link="leg_link" />
        <child link="leg_base_link" />
    </joint>

    <link name="right_wheel_link">
        <visual>
            <geometry>
                <cylinder radius="0.12" length="0.12" />
            </geometry>
            <material name="white"></material>
            <collision>
                <geometry>
                    <cylinder radius="0.12" length="0.12" />
                </geometry>
            </collision>
            <inertial>
                <mass value="1.0" />
                <inertia ixx="1.0" ixy="0.0" ixz="0.0" iyy="1.0" iyz="0.0" izz="1.0" />
            </inertial>
        </visual>
    </link>

    <joint name="leg_base_to_right_wheel_joint" type="continuous">
        <parent link="leg_base_link" />
        <child link="right_wheel_link" />
        <origin xyz="0.3 0.0 0.0" rpy="0.0 1.57075 0.0" />
        <axis xyz="0.0 0 1.0" />

    </joint>

    <link name="left_wheel_link">
        <visual>
            <geometry>
                <cylinder radius="0.12" length="0.12" />
            </geometry>
            <material name="white"></material>
        </visual>
        <collision>
            <geometry>
                <cylinder radius="0.12" length="0.12" />
            </geometry>
        </collision>
        <inertial>
            <mass value="1.0" />
            <inertia ixx="1.0" ixy="0.0" ixz="0.0" iyy="1.0" iyz="0.0" izz="1.0" />
        </inertial>
    </link>


    <joint name="leg_base_to_left_wheel_joint" type="continuous">
        <parent link="leg_base_link" />
        <child link="left_wheel_link" />
        <origin xyz="-0.3 0.0 0.0" rpy="0.0 1.57075 0.0" />
        <axis xyz="0.0 0.0 1.0" />

    </joint>

    <link name="front_leg_link">
        <visual>
            <geometry>
                <box size="0.1 0.1 0.2" />
            </geometry>
        </visual>
        <collision>
            <geometry>
                <box size="0.1 0.1 0.2" />
            </geometry>
        </collision>
        <inertial>
            <mass value="3.0" />
            <inertia ixx="1.0" ixy="0.0" ixz="0.0" iyy="1.0" iyz="0.0" izz="1.0" />
        </inertial>
    </link>

    <joint name="base_to_front_leg_joint" type="fixed">
        <origin xyz="0.0 0.3 0.2" rpy="0.0 0.0 0.0" />
        <parent link="base_link" />
        <child link="front_leg_link" />
    </joint>


    <link name="front_base_link">
        <visual>
            <geometry>
                <cylinder
                    radius="0.1" length="0.1" />
            </geometry>
        </visual>
    </link>
    <joint
        name="frontleg_to_frontbase_joint" type="fixed">
        <origin xyz="0.0 0.0 -0.05" rpy="0.0 1.57075 0.0" />
        <parent link="front_leg_link" />
        <child link="front_base_link" />
    </joint>

    <link name="front_wheel_link">
        <visual>
            <geometry>
                <cylinder radius="0.12" length="0.12"/>
            </geometry>
            <material name="white"></material>
        </visual>
    </link>

    <joint name="front_ base_to_wheel_joint" type="continuous">
        <origin xyz="0.038 0.0 0.0" rpy="0.0 0.0 0.0"/>
        <parent link="front_base_link"/>
        <child link="front_wheel_link"/>
        <axis xyz="0.0 0.0 1.0"/>
    </joint>

    <!--    
    <link name="front_leg_base_link">
        <visual>
            <geometry>
                <box
    size="0.2 0.03 0.03" />
            </geometry>
        </visual>
        <collision>
            <geometry>
    <box size="0.5 0.3 0.03" />
            </geometry>
        </collision>
        <inertial>
    <mass value="3.0" />
            <inertia ixx="1.0" ixy="0.0" ixz="0.0" iyy="1.0" iyz="0.0"
    izz="1.0" />
        </inertial>
    </link>

    <joint name="front_leg_to_leg_base_joint"
    type="fixed">
        <origin xyz="0.0 0.0 -0.08" rpy="0.0 0.0 0.0" />
        <parent
    link="front_leg_link" />
        <child link="front_leg_base_link" />
    </joint> -->

    <!-- <link name="front_base_right_link">
        <visual>
            <geometry>
                <box
    size="0.03 0.03 0.1"/>
            </geometry>
        </visual>        
        <collision>
    <geometry>
                <box size="0.0 0.0 0.0"/>
            </geometry>
        </collision>
    <inertial>
            <mass value="2.0" />
            <inertia ixx="1.0" ixy="0.0" ixz="0.0"
    iyy="1.0" iyz="0.0" izz="1.0" />
        </inertial>
    </link>
    <joint
    name="front_to_right_joint" type="fixed">
        <origin xyz="-0.1 0.0 -0.035" rpy="0.0 0.0
    0.0"/>
        <parent link="front_leg_base_link"/>
        <child
    link="front_base_right_link"/>
    </joint>

    <link name="front_base_left_link">
        <visual>
    <geometry>
                <box size="0.03 0.03 0.1"/>
            </geometry>
        </visual>
    <collision>
            <geometry>
                <box size="0.0 0.0 0.0"/>
            </geometry>
    </collision>
        <inertial>
            <mass value="2.0" />
            <inertia ixx="1.0"
    ixy="0.0" ixz="0.0" iyy="1.0" iyz="0.0" izz="1.0" />
        </inertial>
    </link>
    <joint
    name="front_to_left_joint" type="fixed">
        <origin xyz="0.1 0.0 -0.035" rpy="0.0 0.0
    0.0"/>
        <parent link="front_leg_base_link"/>
        <child link="front_base_left_link"/>
    </joint> -->

</robot>    