<?xml version="1.0" encoding="UTF-8"?>
<robot name="multipleshapes">

    <material name="blue">
        <color rgba="0 0 1 1" />
    </material>

    <material name="white">
        <color rgba="1 1 1 1" />
    </material>

    <link name="base_link">
        <visual>
            <geometry>
                <box size="0.9 1.6 0.4" />
            </geometry>
            <origin rpy="0.0 0.0 0.0" xyz="0.0 0.0 0.3" />
            <material name="blue">
            </material>
        </visual>
        <collision>
            <geometry>
                <box size="0.9 1.6 0.4" />
            </geometry>
            <origin rpy="0.0 0.0 0.0" xyz="0.0 0.0 0.3" />
        </collision>
        <inertial>
            <mass value="10.0" />
            <inertia ixx="1.0" ixy="0.0" ixz="0.0" iyy="1.0" iyz="0.0" izz="1.0" />
        </inertial>

    </link>

    <link name="front_left">
        <visual>
            <geometry>
                <sphere radius="0.1" />
            </geometry>
            <origin xyz="-0.24 0.7 -0.5" rpy="0.0 0.0 0.0" />
        </visual>
        <collision>
            <geometry>
                <sphere radius="0.1" />
            </geometry>
            <origin xyz="-0.24 0.7 -0.5" rpy="0.0 0.0 0.0" />
        </collision>
        <inertial>
            <mass value="1.0" />
            <inertia ixx="1.0" ixy="0.0" ixz="0.0" iyy="1.0" iyz="0.0" izz="1.0" />
        </inertial>
    </link>

    <joint name="base_to_frontleft" type="fixed">
        <origin xyz="0.0 0.0 0.0" rpy="1.0 0.0 0.0" />
        <parent link="base_link" />
        <child link="front_left" />
    </joint>


    <link name="front_right">
        <visual>
            <geometry>
                <sphere radius="0.1" />
            </geometry>
            <origin xyz="0.24 0.7 -0.5" rpy="0.0 0.0 0.0" />
        </visual>
        <collision>
            <geometry>
                <sphere radius="0.1" />
            </geometry>
            <origin xyz="0.24 0.7 -0.5" rpy="0.0 0.0 0.0" />
        </collision>
        <inertial>
            <mass value="1.0" />
            <inertia ixx="1.0" ixy="0.0" ixz="0.0" iyy="1.0" iyz="0.0" izz="1.0" />
        </inertial>

    </link>

    <joint name="base_to_frontright" type="fixed">
        <origin xyz="0.0 0.0 0.0" rpy="1.0 0.0 0.0" />
        <parent link="base_link" />
        <child link="front_right" />
    </joint>

    <link name="front_link">
        <visual>
            <geometry>
                <box size="0.1 0.1 1.3" />
            </geometry>
            <origin xyz="-0.1 0.0 0.0" rpy="0.0 0.0 0.0" />
        </visual>
        <collision>
            <geometry>
                <box size="0.1 0.1 1.3" />
            </geometry>
            <origin xyz="-0.1 0.0 0.0" rpy="0.0 0.0 0.0" />
        </collision>
        <inertial>
            <mass value="3.0" />
            <inertia ixx="1.0" ixy="0.0" ixz="0.0" iyy="1.0" iyz="0.0" izz="1.0" />
        </inertial>

    </link>

    <joint name="base_to_front" type="fixed">
        <origin xyz="0.0 0.5 0.0" rpy="0.0 1.57075 0.0" />
        <parent link="base_link" />
        <child link="front_link" />
    </joint>

    <link name="back_link">
        <visual>
            <geometry>
                <box size="0.1 0.1 1.3" />
            </geometry>
            <origin xyz="-0.1 0.0 0.0" rpy="0.0 0.0 0.0" />
        </visual>
        <collision>
            <geometry>
                <box size="0.1 0.1 1.3" />
            </geometry>
            <origin xyz="-0.1 0.0 0.0" rpy="0.0 0.0 0.0" />
        </collision>
        <inertial>
            <mass value="3.0" />
            <inertia ixx="1.0" ixy="0.0" ixz="0.0" iyy="1.0" iyz="0.0" izz="1.0" />
        </inertial>
    </link>

    <joint name="base_to_back" type="fixed">
        <origin xyz="0.0 -0.5 0.0" rpy="0.0 1.57075 0.0" />
        <parent link="base_link" />
        <child link="back_link" />
    </joint>

    <link name="front_right_wheel">
        <visual>
            <geometry>
                <cylinder radius="0.17" length="0.15" />
            </geometry>
            <material name="white"></material>
            <collision>
                <geometry>
                    <cylinder radius="0.17" length="0.15" />
                </geometry>
            </collision>
            <inertial>
                <mass value="1.0" />
                <inertia ixx="1.0" ixy="0.0" ixz="0.0" iyy="1.0" iyz="0.0" izz="1.0" />
            </inertial>
        </visual>
    </link>

    <joint name="front_to_front_right_wheel" type="continuous">
        <parent link="front_link" />
        <child link="front_right_wheel" />
        <origin xyz="-0.1 0.0 0.6" rpy="0.0 0.0 0.0" />
        <axis xyz="0.0 0 1.0" />

    </joint>

    <link name="front_left_wheel">
        <visual>
            <geometry>
                <cylinder radius="0.17" length="0.15" />
            </geometry>
            <material name="white"></material>
        </visual>
        <collision>
            <geometry>
                <cylinder radius="0.17" length="0.15" />
            </geometry>
        </collision>
        <inertial>
            <mass value="1.0" />
            <inertia ixx="1.0" ixy="0.0" ixz="0.0" iyy="1.0" iyz="0.0" izz="1.0" />
        </inertial>
    </link>


    <joint name="front_to_front_left_wheel" type="continuous">
        <parent link="front_link" />
        <child link="front_left_wheel" />
        <origin xyz="-0.1 0.0 -0.6" rpy="0.0 0.0 0.0" />
        <axis xyz="0.0 0.0 1.0" />

    </joint>

    <link name="back_right_wheel">
        <visual>
            <geometry>
                <cylinder radius="0.17" length="0.15" />
            </geometry>
            <material name="white"></material>
        </visual>
        <collision>
            <geometry>
                <cylinder radius="0.17" length="0.15" />
            </geometry>
        </collision>
        <inertial>
            <mass value="1.0" />
            <inertia ixx="1.0" ixy="0.0" ixz="0.0" iyy="1.0" iyz="0.0" izz="1.0" />
        </inertial>
    </link>

    <joint name="back_to_back_right_wheel" type="continuous">
        <parent link="back_link" />
        <child link="back_right_wheel" />
        <origin xyz="-0.1 0.0 0.6" rpy="0.0 0.0 0.0" />
        <axis xyz="0.0 0.0 1.0" />

    </joint>

    <link name="back_left_wheel">
        <visual>
            <geometry>
                <cylinder radius="0.17" length="0.15" />
            </geometry>
            <material name="white"></material>
        </visual>
        <collision>
            <geometry>
                <cylinder radius="0.17" length="0.15" />
            </geometry>
        </collision>
        <inertial>
            <mass value="1.0" />
            <inertia ixx="1.0" ixy="0.0" ixz="0.0" iyy="1.0" iyz="0.0" izz="1.0" />
        </inertial>
    </link>

    <joint name="back_to_back_left_wheel" type="continuous">
        <parent link="back_link" />
        <child link="back_left_wheel" />
        <origin xyz="-0.1 0.0 -0.6" rpy="0.0 0.0 0.0" />
        <axis xyz="0.0 0.0 1.0" />
    </joint>
</robot>    