<sdf version='1.7'>
  <model name='myRobot'>
    <link name='base_footprint'>
      <inertial>
        <pose>0.037209 0 0.283023 0 -0 0</pose>
        <mass>21.5</mass>
        <inertia>
          <ixx>14.941</ixx>
          <ixy>0</ixy>
          <ixz>-0.692581</ixz>
          <iyy>16.0323</iyy>
          <iyz>0</iyz>
          <izz>10.1491</izz>
        </inertia>
      </inertial>
      <collision name='base_footprint_fixed_joint_lump__base_link_collision'>
        <pose>0 0 0.9 0 -0 0</pose>
        <geometry>
          <cylinder>
            <length>1.3</length>
            <radius>0.5</radius>
          </cylinder>
        </geometry>
        <surface>
          <contact>
            <ode/>
          </contact>
          <friction>
            <ode/>
          </friction>
        </surface>
      </collision>
      <collision name='base_footprint_fixed_joint_lump__back_leg_link_collision_1'>
        <pose>-0.3 0 0.2 0 -0 0</pose>
        <geometry>
          <box>
            <size>0.1 0.1 0.2</size>
          </box>
        </geometry>
        <surface>
          <contact>
            <ode/>
          </contact>
          <friction>
            <ode/>
          </friction>
        </surface>
      </collision>
      <collision name='base_footprint_fixed_joint_lump__back_leg_base_link_collision_2'>
        <pose>-0.3 0 0.12 0 -0 1.57075</pose>
        <geometry>
          <box>
            <size>0.5 0.1 0.1</size>
          </box>
        </geometry>
      </collision>
      <collision name='base_footprint_fixed_joint_lump__front_leg_link_collision_3'>
        <pose>0.3 0 0.2 0 -0 0</pose>
        <geometry>
          <box>
            <size>0.1 0.1 0.2</size>
          </box>
        </geometry>
        <surface>
          <contact>
            <ode/>
          </contact>
          <friction>
            <ode/>
          </friction>
        </surface>
      </collision>
      <collision name='base_footprint_fixed_joint_lump__caster_wheel_link_collision_4'>
        <pose>0.3 0 0.11 0 -0 0</pose>
        <geometry>
          <sphere>
            <radius>0.12</radius>
          </sphere>
        </geometry>
        <surface>
          <contact>
            <ode/>
          </contact>
          <friction>
            <ode>
              <mu>0</mu>
              <mu2>0</mu2>
            </ode>
          </friction>
        </surface>
      </collision>
      <collision name='base_footprint_fixed_joint_lump__head_link_collision_5'>
        <pose>0 0 1.5 0 -0 0</pose>
        <geometry>
          <sphere>
            <radius>0.5</radius>
          </sphere>
        </geometry>
        <surface>
          <contact>
            <ode/>
          </contact>
          <friction>
            <ode/>
          </friction>
        </surface>
      </collision>
      <collision name='base_footprint_fixed_joint_lump__head_left_link_collision_6'>
        <pose>0.5 0.17 1.7 0 -0 0</pose>
        <geometry>
          <sphere>
            <radius>0.1</radius>
          </sphere>
        </geometry>
        <surface>
          <contact>
            <ode/>
          </contact>
          <friction>
            <ode/>
          </friction>
        </surface>
      </collision>
      <collision name='base_footprint_fixed_joint_lump__head_right_link_collision_7'>
        <pose>0.5 -0.17 1.7 0 -0 0</pose>
        <geometry>
          <sphere>
            <radius>0.1</radius>
          </sphere>
        </geometry>
        <surface>
          <contact>
            <ode/>
          </contact>
          <friction>
            <ode/>
          </friction>
        </surface>
      </collision>
      <collision name='base_footprint_fixed_joint_lump__lidar_link_collision_8'>
        <pose>0.6 0 0.25 0 -0 0</pose>
        <geometry>
          <box>
            <size>0.2 0.2 0.15</size>
          </box>
        </geometry>
        <surface>
          <contact>
            <ode/>
          </contact>
          <friction>
            <ode/>
          </friction>
        </surface>
      </collision>
      <visual name='base_footprint_fixed_joint_lump__base_link_visual'>
        <pose>0 0 0.9 0 -0 0</pose>
        <geometry>
          <cylinder>
            <length>1.3</length>
            <radius>0.5</radius>
          </cylinder>
        </geometry>
        <material>
          <script>
            <name>Gazebo/Blue</name>
            <uri>file://media/materials/scripts/gazebo.material</uri>
          </script>
        </material>
      </visual>
      <visual name='base_footprint_fixed_joint_lump__back_leg_link_visual_1'>
        <pose>-0.3 0 0.2 0 -0 0</pose>
        <geometry>
          <box>
            <size>0.1 0.1 0.2</size>
          </box>
        </geometry>
        <material>
          <script>
            <name>Gazebo/White</name>
            <uri>file://media/materials/scripts/gazebo.material</uri>
          </script>
        </material>
      </visual>
      <visual name='base_footprint_fixed_joint_lump__back_leg_base_link_visual_2'>
        <pose>-0.3 0 0.12 0 -0 1.57075</pose>
        <geometry>
          <box>
            <size>0.5 0.1 0.1</size>
          </box>
        </geometry>
      </visual>
      <visual name='base_footprint_fixed_joint_lump__front_leg_link_visual_3'>
        <pose>0.3 0 0.2 0 -0 0</pose>
        <geometry>
          <box>
            <size>0.1 0.1 0.2</size>
          </box>
        </geometry>
        <material>
          <script>
            <name>Gazebo/White</name>
            <uri>file://media/materials/scripts/gazebo.material</uri>
          </script>
        </material>
      </visual>
      <visual name='base_footprint_fixed_joint_lump__caster_wheel_link_visual_4'>
        <pose>0.3 0 0.11 0 -0 0</pose>
        <geometry>
          <sphere>
            <radius>0.12</radius>
          </sphere>
        </geometry>
        <material>
          <script>
            <name>Gazebo/Black</name>
            <uri>file://media/materials/scripts/gazebo.material</uri>
          </script>
        </material>
      </visual>
      <visual name='base_footprint_fixed_joint_lump__head_link_visual_5'>
        <pose>0 0 1.5 0 -0 0</pose>
        <geometry>
          <sphere>
            <radius>0.5</radius>
          </sphere>
        </geometry>
        <material>
          <script>
            <name>Gazebo/White</name>
            <uri>file://media/materials/scripts/gazebo.material</uri>
          </script>
        </material>
      </visual>
      <visual name='base_footprint_fixed_joint_lump__head_left_link_visual_6'>
        <pose>0.5 0.17 1.7 0 -0 0</pose>
        <geometry>
          <sphere>
            <radius>0.1</radius>
          </sphere>
        </geometry>
        <material>
          <script>
            <name>Gazebo/Red</name>
            <uri>file://media/materials/scripts/gazebo.material</uri>
          </script>
        </material>
      </visual>
      <visual name='base_footprint_fixed_joint_lump__head_right_link_visual_7'>
        <pose>0.5 -0.17 1.7 0 -0 0</pose>
        <geometry>
          <sphere>
            <radius>0.1</radius>
          </sphere>
        </geometry>
        <material>
          <script>
            <name>Gazebo/Red</name>
            <uri>file://media/materials/scripts/gazebo.material</uri>
          </script>
        </material>
      </visual>
      <visual name='base_footprint_fixed_joint_lump__lidar_link_visual_8'>
        <pose>0.6 0 0.25 0 -0 0</pose>
        <geometry>
          <box>
            <size>0.2 0.2 0.15</size>
          </box>
        </geometry>
      </visual>
      <sensor name='laser' type='ray'>
        <visualize>1</visualize>
        <update_rate>5</update_rate>
        <ray>
          <scan>
            <horizontal>
              <samples>720</samples>
              <resolution>1</resolution>
              <min_angle>-1.75</min_angle>
              <max_angle>1.75</max_angle>
            </horizontal>
          </scan>
          <range>
            <min>0.25</min>
            <max>10</max>
            <resolution>0.015</resolution>
          </range>
        </ray>
        <plugin name='laser_controller' filename='libgazebo_ros_ray_sensor.so'>
          <ros>
            <argument>~/out:=scan</argument>
          </ros>
          <output_type>sensor_msgs/LaserScan</output_type>
          <frame_name>lidar_link</frame_name>
        </plugin>
        <pose>0.6 0 0.25 0 -0 0</pose>
      </sensor>
    </link>
    <joint name='base_to_left_wheel_joint' type='revolute'>
      <pose relative_to='base_footprint'>-0.3 0.3 0.11 0 -0 0</pose>
      <parent>base_footprint</parent>
      <child>left_wheel_link</child>
      <axis>
        <xyz>0 1 0</xyz>
        <limit>
          <lower>-1e+16</lower>
          <upper>1e+16</upper>
        </limit>
        <dynamics>
          <spring_reference>0</spring_reference>
          <spring_stiffness>0</spring_stiffness>
        </dynamics>
      </axis>
    </joint>
    <link name='left_wheel_link'>
      <pose relative_to='base_to_left_wheel_joint'>0 0 0 0 -0 0</pose>
      <inertial>
        <pose>0 0 0 0 -0 0</pose>
        <mass>1</mass>
        <inertia>
          <ixx>1</ixx>
          <ixy>0</ixy>
          <ixz>0</ixz>
          <iyy>1</iyy>
          <iyz>0</iyz>
          <izz>1</izz>
        </inertia>
      </inertial>
      <collision name='left_wheel_link_collision'>
        <pose>0 0 0 1.57075 -0 0</pose>
        <geometry>
          <cylinder>
            <length>0.12</length>
            <radius>0.12</radius>
          </cylinder>
        </geometry>
        <surface>
          <contact>
            <ode/>
          </contact>
          <friction>
            <ode/>
          </friction>
        </surface>
      </collision>
      <visual name='left_wheel_link_visual'>
        <pose>0 0 0 1.57075 -0 0</pose>
        <geometry>
          <cylinder>
            <length>0.12</length>
            <radius>0.12</radius>
          </cylinder>
        </geometry>
        <material>
          <script>
            <name>Gazebo/Black</name>
            <uri>file://media/materials/scripts/gazebo.material</uri>
          </script>
        </material>
      </visual>
    </link>
    <joint name='base_to_right_wheel_joint' type='revolute'>
      <pose relative_to='base_footprint'>-0.3 -0.3 0.11 0 -0 0</pose>
      <parent>base_footprint</parent>
      <child>right_wheel_link</child>
      <axis>
        <xyz>0 1 0</xyz>
        <limit>
          <lower>-1e+16</lower>
          <upper>1e+16</upper>
        </limit>
        <dynamics>
          <spring_reference>0</spring_reference>
          <spring_stiffness>0</spring_stiffness>
        </dynamics>
      </axis>
    </joint>
    <link name='right_wheel_link'>
      <pose relative_to='base_to_right_wheel_joint'>0 0 0 0 -0 0</pose>
      <inertial>
        <pose>0 0 0 0 -0 0</pose>
        <mass>1</mass>
        <inertia>
          <ixx>1</ixx>
          <ixy>0</ixy>
          <ixz>0</ixz>
          <iyy>1</iyy>
          <iyz>0</iyz>
          <izz>1</izz>
        </inertia>
      </inertial>
      <collision name='right_wheel_link_collision'>
        <pose>0 0 0 1.57075 -0 0</pose>
        <geometry>
          <cylinder>
            <length>0.12</length>
            <radius>0.12</radius>
          </cylinder>
        </geometry>
        <surface>
          <contact>
            <ode/>
          </contact>
          <friction>
            <ode>
              <mu>0.5</mu>
              <mu2>0.5</mu2>
            </ode>
          </friction>
        </surface>
      </collision>
      <visual name='right_wheel_link_visual'>
        <pose>0 0 0 1.57075 -0 0</pose>
        <geometry>
          <cylinder>
            <length>0.12</length>
            <radius>0.12</radius>
          </cylinder>
        </geometry>
        <material>
          <script>
            <name>Gazebo/Black</name>
            <uri>file://media/materials/scripts/gazebo.material</uri>
          </script>
        </material>
      </visual>
      <mu3 value='0.5'/>
    </link>
    <plugin name='diff_drive' filename='libgazebo_ros_diff_drive.so'>
      <update_rate>10</update_rate>
      <left_joint>base_to_left_wheel_joint</left_joint>
      <right_joint>base_to_right_wheel_joint</right_joint>
      <wheel_separation>0.6</wheel_separation>
      <wheel_diameter>0.12</wheel_diameter>
      <cmd_vel_timeout>0.5</cmd_vel_timeout>
      <odometry_frame>odom</odometry_frame>
      <robot_base_frame>base_footprint</robot_base_frame>
      <publish_odom>1</publish_odom>
      <publish_odom_tf>1</publish_odom_tf>
      <publish_wheel_tf>0</publish_wheel_tf>
    </plugin>
    <plugin name='joint_state_publisher' filename='libgazebo_ros_joint_state_publisher.so'>
      <update_rate>10</update_rate>
      <joint_name>base_to_left_wheel_joint</joint_name>
      <joint_name>base_to_right_wheel_joint</joint_name>
    </plugin>
    <frame name='back_leg_to_leg_base_joint' attached_to='back_leg_link'>
      <pose>0 0 -0.08 0 -0 1.57075</pose>
    </frame>
    <frame name='back_leg_base_link' attached_to='back_leg_to_leg_base_joint'/>
    <frame name='base_to_back_leg_joint' attached_to='base_link'>
      <pose>-0.3 0 0.2 0 -0 0</pose>
    </frame>
    <frame name='back_leg_link' attached_to='base_to_back_leg_joint'/>
    <frame name='front_leg_to_caster_joint' attached_to='front_leg_link'>
      <pose>0 0 -0.09 0 -0 0</pose>
    </frame>
    <frame name='caster_wheel_link' attached_to='front_leg_to_caster_joint'/>
    <frame name='base_to_front_leg_joint' attached_to='base_link'>
      <pose>0.3 0 0.2 0 -0 0</pose>
    </frame>
    <frame name='front_leg_link' attached_to='base_to_front_leg_joint'/>
    <frame name='base_to_head_joint' attached_to='base_link'>
      <pose>0 0 1.5 0 -0 0</pose>
    </frame>
    <frame name='head_link' attached_to='base_to_head_joint'/>
    <frame name='base_to_head_left_joint' attached_to='base_link'>
      <pose>0.5 0.17 1.7 0 -0 0</pose>
    </frame>
    <frame name='head_left_link' attached_to='base_to_head_left_joint'/>
    <frame name='base_to_head_right_joint' attached_to='base_link'>
      <pose>0.5 -0.17 1.7 0 -0 0</pose>
    </frame>
    <frame name='head_right_link' attached_to='base_to_head_right_joint'/>
    <frame name='base_to_lidar_joint' attached_to='base_link'>
      <pose>0.6 0 0.25 0 -0 0</pose>
    </frame>
    <frame name='lidar_link' attached_to='base_to_lidar_joint'/>
    <frame name='base_to_footprint_joint' attached_to='base_footprint'>
      <pose>0 0 0 0 -0 0</pose>
    </frame>
    <frame name='base_link' attached_to='base_to_footprint_joint'/>
  </model>
</sdf>
